Workbook

Sheet Raw_Data
A1: PO_Number | B1: PO_Date | C1: Vendor_ID | D1: Vendor_Name | E1: Department | F1: Category | G1: Item_ID | H1: Item_Description | I1: Quantity | J1: Unit_Price_INR | K1: PO_Amount_INR | L1: Payment_Terms | M1: Expected_Delivery_Date | N1: Actual_Delivery_Date | O1: Region | P1: Buyer | Q1: PO_Status | R1: Delivery_Status
A2: PO202500001 | B2: 45772 | C2: V002 | D2: Metro Business Supplies | E2: Finance | F2: Office Supplies | G2: ITM001 | H2: A4 Copier Paper - 500 Sheets | I2: 39 | J2: 232.61 | K2: 9071.79 | L2: Net 30 | M2: 45778 | N2: 45778 | O2: West | P2: Kavya Iyer | Q2: Closed | R2: On Time
A3: PO202600002 | B3: 46175 | C3: V002 | D3: Metro Business Supplies | E3: Sales & Marketing | F3: Office Supplies | G3: ITM003 | H3: Ergonomic Office Chair | I3: 8 | J3: 7237.73 | K3: 57901.84 | L3: Net 45 | M3: 46189 | N3: 46189 | O3: West | P3: Ishita Shah | Q3: Closed | R3: On Time
A4: PO202500003 | B4: 46006 | C4: V003 | D4: Prime Workplace India | E4: Operations | F4: Facilities | G4: ITM010 | H4: Printer Maintenance Kit | I4: 14 | J4: 5597.17 | K4: 78360.38 | L4: Net 45 | M4: 46016 | N4: 46016 | O4: South | P4: Rohit Mehta | Q4: Closed | R4: On Time
A5: PO202500004 | B5: 45738 | C5: V015 | D5: TalentBridge Consulting | E5: IT | F5: Professional Services | G5: ITM020 | H5: Audit Support - Monthly | I5: 1 | J5: 53142.53 | K5: 53142.53 | L5: Net 60 | M5: 45755 | N5: 45755 | O5: South | P5: Vikram Reddy | Q5: Closed | R5: On Time
A6: PO202500005 | B6: 45942 | C6: V005 | D6: Vertex Digital Systems | E6: IT | F6: Technology | G6: ITM006 | H6: Business Laptop - Standard | I6: 2 | J6: 64463.55 | K6: 128927.1 | L6: Net 30 | M6: 45956 | N6: 45955 | O6: East | P6: Vikram Reddy | Q6: Closed | R6: On Time
A7: PO202500006 | B7: 45715 | C7: V003 | D7: Prime Workplace India | E7: Operations | F7: Facilities | G7: ITM013 | H7: Electrical Maintenance Service | I7: 6 | J7: 19379.08 | K7: 116274.48 | L7: Net 60 | M7: 45723 | N7: 45720 | O7: East | P7: Ananya Rao | Q7: Closed | R7: On Time
A8: PO202500007 | B8: 45929 | C8: V016 | D8: StratEdge Partners | E8: IT | F8: Professional Services | G8: ITM022 | H8: Data Reporting Support - Monthly | I8: 1 | J8: 46371.25 | K8: 46371.25 | L8: Net 45 | M8: 45936 | N8: 45936 | O8: South | P8: Vikram Reddy | Q8: Closed | R8: On Time
A9: PO202600008 | B9: 46090 | C9: V006 | D9: CoreTech Solutions | E9: Human Resources | F9: Technology | G9: ITM007 | H9: USB-C Docking Station | I9: 14 | J9: 8482.87 | K9: 118760.18 | L9: Net 45 | M9: 46095 | N9: 46095 | O9: North | P9: Neha Kapoor | Q9: Closed | R9: On Time
A10: PO202500009 | B10: 45772 | C10: V003 | D10: Prime Workplace India | E10: Operations | F10: Office Supplies | G10: ITM003 | H10: Ergonomic Office Chair | I10: 9 | J10: 8210 | K10: 73890 | L10: Net 60 | M10: 45789 | N10: 45789 | O10: North | P10: Ananya Rao | Q10: Closed | R10: On Time
A11: PO202500010 | B11: 45814 | C11: V011 | D11: ProSafe Equipment | E11: Operations | F11: Safety | G11: ITM014 | H11: Safety Gloves - Box | I11: 12 | J11: 686.72 | K11: 8240.64 | L11: Net 30 | M11: 45824 | N11: 45822 | O11: West | P11: Ananya Rao | Q11: Closed | R11: On Time
A12: PO202500011 | B12: 45745 | C12: V006 | D12: CoreTech Solutions | E12: IT | F12: Technology | G12: ITM005 | H12: 24-inch Business Monitor | I12: 3 | J12: 10652.85 | K12: 31958.55 | L12: Net 60 | M12: 45754 | N12: 45751 | O12: West | P12: Vikram Reddy | Q12: Closed | R12: On Time
A13: PO202600012 | B13: 46040 | C13: V012 | D13: BrightReach Media | E13: Sales & Marketing | F13: Marketing | G13: ITM017 | H13: Digital Marketing Campaign | I13: 3 | J13: 41597.96 | K13: 124793.88 | L13: Net 30 | M13: 46053 | N13: 46052 | O13: South | P13: Arjun Nair | Q13: Closed | R13: On Time
... A45: PO202600044 | B45: 46158 | C45: V014 | D45: Insight Advisory Services | E45: Finance | F45: Professional Services | G45: ITM022 | H45: Data Reporting Support - Monthly | I45: 1 | J45: 46154.49 | K45: 46154.49 | L45: Net 30 | M45: 46166 | N45: 46165 | O45: North | P45: Kavya Iyer | Q45: Closed | R45: On Time
A46: PO202600045 | B46: 46201 | C46: V014 | D46: Insight Advisory Services | E46: Administration | F46: Professional Services | G46: ITM021 | H46: Recruitment Service Fee | I46: 1 | J46: 45037.67 | K46: 45037.67 | L46: Net 45 | M46: 46210 | O46: West | P46: Meera Joshi | Q46: Open | R46: Open
A47: PO202500046 | B47: 45941 | C47: V016 | D47: StratEdge Partners | E47: Administration | F47: Professional Services | G47: ITM021 | H47: Recruitment Service Fee | I47: 1 | J47: 45174.98 | K47: 45174.98 | L47: Net 30 | M47: 45949 | N47: 45947 | O47: West | P47: Meera Joshi | Q47: Closed | R47: On Time
A48: PO202500047 | B48: 45957 | C48: V009 | D48: Urban Maintenance Co. | E48: Operations | F48: Facilities | G48: ITM010 | H48: Printer Maintenance Kit | I48: 8 | J48: 5244.48 | K48: 41955.84 | L48: Net 60 | M48: 45969 | N48: 45968 | O48: North | P48: Rohit Mehta | Q48: Closed | R48: On Time
A49: PO202600048 | B49: 46068 | C49: V001 | D49: Apex Office Solutions | E49: Sales & Marketing | F49: Office Supplies | G49: ITM001 | H49: A4 Copier Paper - 500 Sheets | I49: 24 | J49: 253.09 | K49: 6074.16 | L49: Net 45 | M49: 46074 | N49: 46074 | O49: East | P49: Arjun Nair | Q49: Closed | R49: On Time
A50: PO202600049 | B50: 46193 | C50: V003 | D50: Prime Workplace India | E50: Administration | F50: Facilities | G50: ITM013 | H50: Electrical Maintenance Service | I50: 2 | J50: 20109.59 | K50: 40219.18 | L50: Net 30 | M50: 46210 | O50: West | P50: Meera Joshi | Q50: Open | R50: Open
A51: PO202500050 | B51: 45734 | C51: V006 | D51: CoreTech Solutions | E51: Human Resources | F51: Technology | G51: ITM008 | H51: Network Switch - 24 Port | I51: 5 | J51: 14721.39 | K51: 73606.95 | L51: Net 30 | M51: 45750 | N51: 45747 | O51: West | P51: Neha Kapoor | Q51: Closed | R51: On Time
A52: PO202500051 | B52: 45860 | C52: V003 | D52: Prime Workplace India | E52: Sales & Marketing | F52: Office Supplies | G52: ITM001 | H52: A4 Copier Paper - 500 Sheets | I52: 9 | J52: 271.17 | K52: 2440.53 | L52: Net 45 | M52: 45865 | N52: 45863 | O52: North | P52: Ishita Shah | Q52: Closed | R52: On Time
A53: PO202500052 | B53: 45785 | C53: V015 | D53: TalentBridge Consulting | E53: Finance | F53: Professional Services | G53: ITM021 | H53: Recruitment Service Fee | I53: 1 | J53: 47911.86 | K53: 47911.86 | L53: Net 45 | M53: 45799 | N53: 45807 | O53: North | P53: Kavya Iyer | Q53: Closed | R53: Late
A54: PO202500053 | B54: 45751 | C54: V006 | D54: CoreTech Solutions | E54: IT | F54: Technology | G54: ITM009 | H54: Annual Software License | I54: 3 | J54: 20717.88 | K54: 62153.64 | L54: Net 60 | M54: 45763 | N54: 45760 | O54: West | P54: Vikram Reddy | Q54: Closed | R54: On Time
A55: PO202600054 | B55: 46139 | C55: V007 | D55: SecureNet Systems | E55: Finance | F55: Technology | G55: ITM004 | H55: Wireless Keyboard & Mouse | I55: 49 | J55: 1867.53 | K55: 91508.97 | L55: Net 45 | M55: 46151 | N55: 46148 | O55: South | P55: Kavya Iyer | Q55: Closed | R55: On Time
A56: PO202500055 | B56: 45748 | C56: V015 | D56: TalentBridge Consulting | E56: Finance | F56: Professional Services | G56: ITM019 | H56: Training Workshop - Per Batch | I56: 2 | J56: 40635.81 | K56: 81271.62 | L56: Net 45 | M56: 45753 | N56: 45751 | O56: East | P56: Kavya Iyer | Q56: Closed | R56: On Time
A57: PO202500056 | B57: 45710 | C57: V007 | D57: SecureNet Systems | E57: Sales & Marketing | F57: Technology | G57: ITM007 | H57: USB-C Docking Station | I57: 1 | J57: 9110.9 | K57: 9110.9 | L57: Net 45 | M57: 45725 | N57: 45724 | O57: North | P57: Arjun Nair | Q57: Closed | R57: On Time
A58: PO202600057 | B58: 46075 | C58: V003 | D58: Prime Workplace India | E58: Administration | F58: Office Supplies | G58: ITM002 | H58: Black Toner Cartridge | I58: 3 | J58: 3638.09 | K58: 10914.27 | L58: Net 30 | M58: 46087 | N58: 46085 | O58: North | P58: Meera Joshi | Q58: Closed | R58: On Time
A59: PO202500058 | B59: 45907 | C59: V002 | D59: Metro Business Supplies | E59: Operations | F59: Office Supplies | G59: ITM003 | H59: Ergonomic Office Chair | I59: 14 | J59: 7537.92 | K59: 105530.88 | L59: Net 30 | M59: 45913 | N59: 45910 | O59: North | P59: Ananya Rao | Q59: Closed | R59: On Time
A60: PO202500059 | B60: 45947 | C60: V014 | D60: Insight Advisory Services | E60: IT | F60: Professional Services | G60: ITM020 | H60: Audit Support - Monthly | I60: 1 | J60: 52186.72 | K60: 52186.72 | L60: Net 30 | M60: 45960 | N60: 45957 | O60: North | P60: Vikram Reddy | Q60: Closed | R60: On Time
A61: PO202500060 | B61: 45902 | C61: V003 | D61: Prime Workplace India | E61: Operations | F61: Facilities | G61: ITM010 | H61: Printer Maintenance Kit | I61: 15 | J61: 5792.84 | K61: 86892.6 | L61: Net 30 | M61: 45919 | N61: 45918 | O61: South | P61: Ananya Rao | Q61: Closed | R61: On Time
A62: PO202600061 | B62: 46108 | C62: V001 | D62: Apex Office Solutions | E62: Administration | F62: Office Supplies | G62: ITM003 | H62: Ergonomic Office Chair | I62: 3 | J62: 8585.36 | K62: 25756.08 | L62: Net 30 | M62: 46114 | N62: 46112 | O62: East | P62: Meera Joshi | Q62: Closed | R62: On Time
... A96: PO202500095 | B96: 45948 | C96: V014 | D96: Insight Advisory Services | E96: Administration | F96: Professional Services | G96: ITM020 | H96: Audit Support - Monthly | I96: 1 | J96: 52647.22 | K96: 52647.22 | L96: Net 30 | M96: 45958 | N96: 45955 | O96: South | P96: Meera Joshi | Q96: Closed | R96: On Time
A97: PO202600096 | B97: 46197 | C97: V014 | D97: Insight Advisory Services | E97: IT | F97: Professional Services | G97: ITM019 | H97: Training Workshop - Per Batch | I97: 1 | J97: 37096.5 | K97: 37096.5 | L97: Net 60 | M97: 46207 | O97: West | P97: Vikram Reddy | Q97: Open | R97: Open
A98: PO202500097 | B98: 45761 | C98: V001 | D98: Apex Office Solutions | E98: Sales & Marketing | F98: Office Supplies | G98: ITM003 | H98: Ergonomic Office Chair | I98: 13 | J98: 7724.41 | K98: 100417.33 | L98: Net 30 | M98: 45775 | N98: 45772 | O98: West | P98: Arjun Nair | Q98: Closed | R98: On Time
A99: PO202600098 | B99: 46106 | C99: V007 | D99: SecureNet Systems | E99: Human Resources | F99: Technology | G99: ITM005 | H99: 24-inch Business Monitor | I99: 8 | J99: 11594.83 | K99: 92758.64 | L99: Net 60 | M99: 46114 | N99: 46112 | O99: East | P99: Neha Kapoor | Q99: Closed | R99: On Time
A100: PO202600099 | B100: 46109 | C100: V016 | D100: StratEdge Partners | E100: Finance | F100: Professional Services | G100: ITM022 | H100: Data Reporting Support - Monthly | I100: 3 | J100: 48120.7 | K100: 144362.1 | L100: Net 45 | M100: 46116 | N100: 46116 | O100: North | P100: Kavya Iyer | Q100: Closed | R100: On Time
A101: PO202500100 | B101: 45949 | C101: V009 | D101: Urban Maintenance Co. | E101: Operations | F101: Facilities | G101: ITM011 | H101: Cleaning Supplies Kit | I101: 19 | J101: 1254.86 | K101: 23842.34 | L101: Net 60 | M101: 45967 | N101: 45965 | O101: East | P101: Ananya Rao | Q101: Closed | R101: On Time
A102: PO202600101 | B102: 46063 | C102: V001 | D102: Apex Office Solutions | E102: Operations | F102: Office Supplies | G102: ITM002 | H102: Black Toner Cartridge | I102: 2 | J102: 3114.35 | K102: 6228.7 | L102: Net 45 | M102: 46081 | N102: 46079 | O102: West | P102: Ananya Rao | Q102: Closed | R102: On Time
A103: PO202600102 | B103: 46138 | C103: V001 | D103: Apex Office Solutions | E103: Operations | F103: Office Supplies | G103: ITM001 | H103: A4 Copier Paper - 500 Sheets | I103: 40 | J103: 253.61 | K103: 10144.4 | L103: Net 30 | M103: 46154 | N103: 46151 | O103: North | P103: Ananya Rao | Q103: Closed | R103: On Time
A104: PO202500103 | B104: 45966 | C104: V010 | D104: SafeGuard Industrial | E104: Operations | F104: Safety | G104: ITM016 | H104: First Aid Refill Kit | I104: 36 | J104: 2057.32 | K104: 74063.52 | L104: Net 45 | M104: 45980 | N104: 45979 | O104: North | P104: Rohit Mehta | Q104: Closed | R104: On Time
...

Sheet Cleaned_Data
A1: PO_Number | B1: PO_Date | C1: Vendor_ID | D1: Vendor_Name | E1: Department | F1: Category | G1: Item_ID | H1: Item_Description | I1: Quantity | J1: Unit_Price_INR | K1: PO_Amount_INR | L1: Payment_Terms | M1: Expected_Delivery_Date | N1: Actual_Delivery_Date | O1: Region | P1: Buyer | Q1: PO_Status | R1: Delivery_Status | S1: Year | T1: Month | U1: Year_Month | V1: Days_Late | W1: On_Time_Flag
A2: PO202500001 | B2: 45772 | C2: V002 | D2: Metro Business Supplies | E2: Finance | F2: Office Supplies | G2: ITM001 | H2: A4 Copier Paper - 500 Sheets | I2: 39 | J2: 232.61 | K2: 9071.79 | L2: Net 30 | M2: 45778 | N2: 45778 | O2: West | P2: Kavya Iyer | Q2: Closed | R2: On Time | S2: 2025 | T2: Apr | U2: 2025-04 | V2: 0 | W2: 1
A3: PO202600002 | B3: 46175 | C3: V002 | D3: Metro Business Supplies | E3: Sales & Marketing | F3: Office Supplies | G3: ITM003 | H3: Ergonomic Office Chair | I3: 8 | J3: 7237.73 | K3: 57901.84 | L3: Net 45 | M3: 46189 | N3: 46189 | O3: West | P3: Ishita Shah | Q3: Closed | R3: On Time | S3: 2026 | T3: Jun | U3: 2026-06 | V3: 0 | W3: 1
A4: PO202500003 | B4: 46006 | C4: V003 | D4: Prime Workplace India | E4: Operations | F4: Facilities | G4: ITM010 | H4: Printer Maintenance Kit | I4: 14 | J4: 5597.17 | K4: 78360.38 | L4: Net 45 | M4: 46016 | N4: 46016 | O4: South | P4: Rohit Mehta | Q4: Closed | R4: On Time | S4: 2025 | T4: Dec | U4: 2025-12 | V4: 0 | W4: 1
A5: PO202500004 | B5: 45738 | C5: V015 | D5: TalentBridge Consulting | E5: IT | F5: Professional Services | G5: ITM020 | H5: Audit Support - Monthly | I5: 1 | J5: 53142.53 | K5: 53142.53 | L5: Net 60 | M5: 45755 | N5: 45755 | O5: South | P5: Vikram Reddy | Q5: Closed | R5: On Time | S5: 2025 | T5: Mar | U5: 2025-03 | V5: 0 | W5: 1
A6: PO202500005 | B6: 45942 | C6: V005 | D6: Vertex Digital Systems | E6: IT | F6: Technology | G6: ITM006 | H6: Business Laptop - Standard | I6: 2 | J6: 64463.55 | K6: 128927.1 | L6: Net 30 | M6: 45956 | N6: 45955 | O6: East | P6: Vikram Reddy | Q6: Closed | R6: On Time | S6: 2025 | T6: Oct | U6: 2025-10 | V6: 0 | W6: 1
A7: PO202500006 | B7: 45715 | C7: V003 | D7: Prime Workplace India | E7: Operations | F7: Facilities | G7: ITM013 | H7: Electrical Maintenance Service | I7: 6 | J7: 19379.08 | K7: 116274.48 | L7: Net 60 | M7: 45723 | N7: 45720 | O7: East | P7: Ananya Rao | Q7: Closed | R7: On Time | S7: 2025 | T7: Feb | U7: 2025-02 | V7: 0 | W7: 1
A8: PO202500007 | B8: 45929 | C8: V016 | D8: StratEdge Partners | E8: IT | F8: Professional Services | G8: ITM022 | H8: Data Reporting Support - Monthly | I8: 1 | J8: 46371.25 | K8: 46371.25 | L8: Net 45 | M8: 45936 | N8: 45936 | O8: South | P8: Vikram Reddy | Q8: Closed | R8: On Time | S8: 2025 | T8: Sep | U8: 2025-09 | V8: 0 | W8: 1
A9: PO202600008 | B9: 46090 | C9: V006 | D9: CoreTech Solutions | E9: Human Resources | F9: Technology | G9: ITM007 | H9: USB-C Docking Station | I9: 14 | J9: 8482.87 | K9: 118760.18 | L9: Net 45 | M9: 46095 | N9: 46095 | O9: North | P9: Neha Kapoor | Q9: Closed | R9: On Time | S9: 2026 | T9: Mar | U9: 2026-03 | V9: 0 | W9: 1
A10: PO202500009 | B10: 45772 | C10: V003 | D10: Prime Workplace India | E10: Operations | F10: Office Supplies | G10: ITM003 | H10: Ergonomic Office Chair | I10: 9 | J10: 8210 | K10: 73890 | L10: Net 60 | M10: 45789 | N10: 45789 | O10: North | P10: Ananya Rao | Q10: Closed | R10: On Time | S10: 2025 | T10: Apr | U10: 2025-04 | V10: 0 | W10: 1
A11: PO202500010 | B11: 45814 | C11: V011 | D11: ProSafe Equipment | E11: Operations | F11: Safety | G11: ITM014 | H11: Safety Gloves - Box | I11: 12 | J11: 686.72 | K11: 8240.64 | L11: Net 30 | M11: 45824 | N11: 45822 | O11: West | P11: Ananya Rao | Q11: Closed | R11: On Time | S11: 2025 | T11: Jun | U11: 2025-06 | V11: 0 | W11: 1
A12: PO202500011 | B12: 45745 | C12: V006 | D12: CoreTech Solutions | E12: IT | F12: Technology | G12: ITM005 | H12: 24-inch Business Monitor | I12: 3 | J12: 10652.85 | K12: 31958.55 | L12: Net 60 | M12: 45754 | N12: 45751 | O12: West | P12: Vikram Reddy | Q12: Closed | R12: On Time | S12: 2025 | T12: Mar | U12: 2025-03 | V12: 0 | W12: 1
A13: PO202600012 | B13: 46040 | C13: V012 | D13: BrightReach Media | E13: Sales & Marketing | F13: Marketing | G13: ITM017 | H13: Digital Marketing Campaign | I13: 3 | J13: 41597.96 | K13: 124793.88 | L13: Net 30 | M13: 46053 | N13: 46052 | O13: South | P13: Arjun Nair | Q13: Closed | R13: On Time | S13: 2026 | T13: Jan | U13: 2026-01 | V13: 0 | W13: 1
... A45: PO202600044 | B45: 46158 | C45: V014 | D45: Insight Advisory Services | E45: Finance | F45: Professional Services | G45: ITM022 | H45: Data Reporting Support - Monthly | I45: 1 | J45: 46154.49 | K45: 46154.49 | L45: Net 30 | M45: 46166 | N45: 46165 | O45: North | P45: Kavya Iyer | Q45: Closed | R45: On Time | S45: 2026 | T45: May | U45: 2026-05 | V45: 0 | W45: 1
A46: PO202600045 | B46: 46201 | C46: V014 | D46: Insight Advisory Services | E46: Administration | F46: Professional Services | G46: ITM021 | H46: Recruitment Service Fee | I46: 1 | J46: 45037.67 | K46: 45037.67 | L46: Net 45 | M46: 46210 | O46: West | P46: Meera Joshi | Q46: Open | R46: Open | S46: 2026 | T46: Jun | U46: 2026-06
A47: PO202500046 | B47: 45941 | C47: V016 | D47: StratEdge Partners | E47: Administration | F47: Professional Services | G47: ITM021 | H47: Recruitment Service Fee | I47: 1 | J47: 45174.98 | K47: 45174.98 | L47: Net 30 | M47: 45949 | N47: 45947 | O47: West | P47: Meera Joshi | Q47: Closed | R47: On Time | S47: 2025 | T47: Oct | U47: 2025-10 | V47: 0 | W47: 1
A48: PO202500047 | B48: 45957 | C48: V009 | D48: Urban Maintenance Co. | E48: Operations | F48: Facilities | G48: ITM010 | H48: Printer Maintenance Kit | I48: 8 | J48: 5244.48 | K48: 41955.84 | L48: Net 60 | M48: 45969 | N48: 45968 | O48: North | P48: Rohit Mehta | Q48: Closed | R48: On Time | S48: 2025 | T48: Oct | U48: 2025-10 | V48: 0 | W48: 1
A49: PO202600048 | B49: 46068 | C49: V001 | D49: Apex Office Solutions | E49: Sales & Marketing | F49: Office Supplies | G49: ITM001 | H49: A4 Copier Paper - 500 Sheets | I49: 24 | J49: 253.09 | K49: 6074.16 | L49: Net 45 | M49: 46074 | N49: 46074 | O49: East | P49: Arjun Nair | Q49: Closed | R49: On Time | S49: 2026 | T49: Feb | U49: 2026-02 | V49: 0 | W49: 1
A50: PO202600049 | B50: 46193 | C50: V003 | D50: Prime Workplace India | E50: Administration | F50: Facilities | G50: ITM013 | H50: Electrical Maintenance Service | I50: 2 | J50: 20109.59 | K50: 40219.18 | L50: Net 30 | M50: 46210 | O50: West | P50: Meera Joshi | Q50: Open | R50: Open | S50: 2026 | T50: Jun | U50: 2026-06
A51: PO202500050 | B51: 45734 | C51: V006 | D51: CoreTech Solutions | E51: Human Resources | F51: Technology | G51: ITM008 | H51: Network Switch - 24 Port | I51: 5 | J51: 14721.39 | K51: 73606.95 | L51: Net 30 | M51: 45750 | N51: 45747 | O51: West | P51: Neha Kapoor | Q51: Closed | R51: On Time | S51: 2025 | T51: Mar | U51: 2025-03 | V51: 0 | W51: 1
A52: PO202500051 | B52: 45860 | C52: V003 | D52: Prime Workplace India | E52: Sales & Marketing | F52: Office Supplies | G52: ITM001 | H52: A4 Copier Paper - 500 Sheets | I52: 9 | J52: 271.17 | K52: 2440.53 | L52: Net 45 | M52: 45865 | N52: 45863 | O52: North | P52: Ishita Shah | Q52: Closed | R52: On Time | S52: 2025 | T52: Jul | U52: 2025-07 | V52: 0 | W52: 1
A53: PO202500052 | B53: 45785 | C53: V015 | D53: TalentBridge Consulting | E53: Finance | F53: Professional Services | G53: ITM021 | H53: Recruitment Service Fee | I53: 1 | J53: 47911.86 | K53: 47911.86 | L53: Net 45 | M53: 45799 | N53: 45807 | O53: North | P53: Kavya Iyer | Q53: Closed | R53: Late | S53: 2025 | T53: May | U53: 2025-05 | V53: 8 | W53: 0
A54: PO202500053 | B54: 45751 | C54: V006 | D54: CoreTech Solutions | E54: IT | F54: Technology | G54: ITM009 | H54: Annual Software License | I54: 3 | J54: 20717.88 | K54: 62153.64 | L54: Net 60 | M54: 45763 | N54: 45760 | O54: West | P54: Vikram Reddy | Q54: Closed | R54: On Time | S54: 2025 | T54: Apr | U54: 2025-04 | V54: 0 | W54: 1
A55: PO202600054 | B55: 46139 | C55: V007 | D55: SecureNet Systems | E55: Finance | F55: Technology | G55: ITM004 | H55: Wireless Keyboard & Mouse | I55: 49 | J55: 1867.53 | K55: 91508.97 | L55: Net 45 | M55: 46151 | N55: 46148 | O55: South | P55: Kavya Iyer | Q55: Closed | R55: On Time | S55: 2026 | T55: Apr | U55: 2026-04 | V55: 0 | W55: 1
A56: PO202500055 | B56: 45748 | C56: V015 | D56: TalentBridge Consulting | E56: Finance | F56: Professional Services | G56: ITM019 | H56: Training Workshop - Per Batch | I56: 2 | J56: 40635.81 | K56: 81271.62 | L56: Net 45 | M56: 45753 | N56: 45751 | O56: East | P56: Kavya Iyer | Q56: Closed | R56: On Time | S56: 2025 | T56: Apr | U56: 2025-04 | V56: 0 | W56: 1
A57: PO202500056 | B57: 45710 | C57: V007 | D57: SecureNet Systems | E57: Sales & Marketing | F57: Technology | G57: ITM007 | H57: USB-C Docking Station | I57: 1 | J57: 9110.9 | K57: 9110.9 | L57: Net 45 | M57: 45725 | N57: 45724 | O57: North | P57: Arjun Nair | Q57: Closed | R57: On Time | S57: 2025 | T57: Feb | U57: 2025-02 | V57: 0 | W57: 1
A58: PO202600057 | B58: 46075 | C58: V003 | D58: Prime Workplace India | E58: Administration | F58: Office Supplies | G58: ITM002 | H58: Black Toner Cartridge | I58: 3 | J58: 3638.09 | K58: 10914.27 | L58: Net 30 | M58: 46087 | N58: 46085 | O58: North | P58: Meera Joshi | Q58: Closed | R58: On Time | S58: 2026 | T58: Feb | U58: 2026-02 | V58: 0 | W58: 1
A59: PO202500058 | B59: 45907 | C59: V002 | D59: Metro Business Supplies | E59: Operations | F59: Office Supplies | G59: ITM003 | H59: Ergonomic Office Chair | I59: 14 | J59: 7537.92 | K59: 105530.88 | L59: Net 30 | M59: 45913 | N59: 45910 | O59: North | P59: Ananya Rao | Q59: Closed | R59: On Time | S59: 2025 | T59: Sep | U59: 2025-09 | V59: 0 | W59: 1
A60: PO202500059 | B60: 45947 | C60: V014 | D60: Insight Advisory Services | E60: IT | F60: Professional Services | G60: ITM020 | H60: Audit Support - Monthly | I60: 1 | J60: 52186.72 | K60: 52186.72 | L60: Net 30 | M60: 45960 | N60: 45957 | O60: North | P60: Vikram Reddy | Q60: Closed | R60: On Time | S60: 2025 | T60: Oct | U60: 2025-10 | V60: 0 | W60: 1
A61: PO202500060 | B61: 45902 | C61: V003 | D61: Prime Workplace India | E61: Operations | F61: Facilities | G61: ITM010 | H61: Printer Maintenance Kit | I61: 15 | J61: 5792.84 | K61: 86892.6 | L61: Net 30 | M61: 45919 | N61: 45918 | O61: South | P61: Ananya Rao | Q61: Closed | R61: On Time | S61: 2025 | T61: Sep | U61: 2025-09 | V61: 0 | W61: 1
A62: PO202600061 | B62: 46108 | C62: V001 | D62: Apex Office Solutions | E62: Administration | F62: Office Supplies | G62: ITM003 | H62: Ergonomic Office Chair | I62: 3 | J62: 8585.36 | K62: 25756.08 | L62: Net 30 | M62: 46114 | N62: 46112 | O62: East | P62: Meera Joshi | Q62: Closed | R62: On Time | S62: 2026 | T62: Mar | U62: 2026-03 | V62: 0 | W62: 1
... A96: PO202500095 | B96: 45948 | C96: V014 | D96: Insight Advisory Services | E96: Administration | F96: Professional Services | G96: ITM020 | H96: Audit Support - Monthly | I96: 1 | J96: 52647.22 | K96: 52647.22 | L96: Net 30 | M96: 45958 | N96: 45955 | O96: South | P96: Meera Joshi | Q96: Closed | R96: On Time | S96: 2025 | T96: Oct | U96: 2025-10 | V96: 0 | W96: 1
A97: PO202600096 | B97: 46197 | C97: V014 | D97: Insight Advisory Services | E97: IT | F97: Professional Services | G97: ITM019 | H97: Training Workshop - Per Batch | I97: 1 | J97: 37096.5 | K97: 37096.5 | L97: Net 60 | M97: 46207 | O97: West | P97: Vikram Reddy | Q97: Open | R97: Open | S97: 2026 | T97: Jun | U97: 2026-06
A98: PO202500097 | B98: 45761 | C98: V001 | D98: Apex Office Solutions | E98: Sales & Marketing | F98: Office Supplies | G98: ITM003 | H98: Ergonomic Office Chair | I98: 13 | J98: 7724.41 | K98: 100417.33 | L98: Net 30 | M98: 45775 | N98: 45772 | O98: West | P98: Arjun Nair | Q98: Closed | R98: On Time | S98: 2025 | T98: Apr | U98: 2025-04 | V98: 0 | W98: 1
A99: PO202600098 | B99: 46106 | C99: V007 | D99: SecureNet Systems | E99: Human Resources | F99: Technology | G99: ITM005 | H99: 24-inch Business Monitor | I99: 8 | J99: 11594.83 | K99: 92758.64 | L99: Net 60 | M99: 46114 | N99: 46112 | O99: East | P99: Neha Kapoor | Q99: Closed | R99: On Time | S99: 2026 | T99: Mar | U99: 2026-03 | V99: 0 | W99: 1
A100: PO202600099 | B100: 46109 | C100: V016 | D100: StratEdge Partners | E100: Finance | F100: Professional Services | G100: ITM022 | H100: Data Reporting Support - Monthly | I100: 3 | J100: 48120.7 | K100: 144362.1 | L100: Net 45 | M100: 46116 | N100: 46116 | O100: North | P100: Kavya Iyer | Q100: Closed | R100: On Time | S100: 2026 | T100: Mar | U100: 2026-03 | V100: 0 | W100: 1
A101: PO202500100 | B101: 45949 | C101: V009 | D101: Urban Maintenance Co. | E101: Operations | F101: Facilities | G101: ITM011 | H101: Cleaning Supplies Kit | I101: 19 | J101: 1254.86 | K101: 23842.34 | L101: Net 60 | M101: 45967 | N101: 45965 | O101: East | P101: Ananya Rao | Q101: Closed | R101: On Time | S101: 2025 | T101: Oct | U101: 2025-10 | V101: 0 | W101: 1
A102: PO202600101 | B102: 46063 | C102: V001 | D102: Apex Office Solutions | E102: Operations | F102: Office Supplies | G102: ITM002 | H102: Black Toner Cartridge | I102: 2 | J102: 3114.35 | K102: 6228.7 | L102: Net 45 | M102: 46081 | N102: 46079 | O102: West | P102: Ananya Rao | Q102: Closed | R102: On Time | S102: 2026 | T102: Feb | U102: 2026-02 | V102: 0 | W102: 1
A103: PO202600102 | B103: 46138 | C103: V001 | D103: Apex Office Solutions | E103: Operations | F103: Office Supplies | G103: ITM001 | H103: A4 Copier Paper - 500 Sheets | I103: 40 | J103: 253.61 | K103: 10144.4 | L103: Net 30 | M103: 46154 | N103: 46151 | O103: North | P103: Ananya Rao | Q103: Closed | R103: On Time | S103: 2026 | T103: Apr | U103: 2026-04 | V103: 0 | W103: 1
A104: PO202500103 | B104: 45966 | C104: V010 | D104: SafeGuard Industrial | E104: Operations | F104: Safety | G104: ITM016 | H104: First Aid Refill Kit | I104: 36 | J104: 2057.32 | K104: 74063.52 | L104: Net 45 | M104: 45980 | N104: 45979 | O104: North | P104: Rohit Mehta | Q104: Closed | R104: On Time | S104: 2025 | T104: Nov | U104: 2025-11 | V104: 0 | W104: 1
...

Sheet Excel_Analysis
A1: Excel Analysis
A3: Total Spend | B3: Total POs | C3: Average PO Value | D3: On-Time Delivery % | E3: Late POs | F3: Top 3 Vendor Share
A4: =SUM(Cleaned_Data!$K$2:$K$2601) -> 1.5786407e+08 | B4: =COUNTA(Cleaned_Data!$A$2:$A$2601) -> 2600 | C4: =A4/B4 -> 60716.949 | D4: =COUNTIF(Cleaned_Data!$R$2:$R$2601,"On Time")/(COUNTIF(Cleaned_Data!$R$2:$R$2601,"On Time")+COUNTIF(Cleaned_Data!$R$2:$R$2601,"Late")) -> 0.9024485 | E4: =COUNTIF(Cleaned_Data!$R$2:$R$2601,"Late") -> 251 | F4: =SUM(J8:J10)/A4 -> 0.3709861
A7: Year_Month | B7: Spend_INR | C7: PO_Count | I7: Vendor | J7: Spend_INR | K7: Spend_Share | L7: Closed_POs | M7: Late_POs | N7: On_Time_%
A8: 2025-01 | B8: =SUMIF(Cleaned_Data!$U$2:$U$2601,A8,Cleaned_Data!$K$2:$K$2601) -> 8281696.5 | C8: =COUNTIF(Cleaned_Data!$U$2:$U$2601,A8) -> 140 | I8: CoreTech Solutions | J8: =SUMIF(Cleaned_Data!$D$2:$D$2601,I8,Cleaned_Data!$K$2:$K$2601) -> 25491861 | K8: =J8/$A$4 -> 0.16147982 | L8: =COUNTIFS(Cleaned_Data!$D$2:$D$2601,I8,Cleaned_Data!$Q$2:$Q$2601,"Closed") -> 294 | M8: =COUNTIFS(Cleaned_Data!$D$2:$D$2601,I8,Cleaned_Data!$R$2:$R$2601,"Late") -> 66 | N8: =IF(L8=0,0,(L8-M8)/L8) -> 0.7755102
A9: 2025-02 | B9: =SUMIF(Cleaned_Data!$U$2:$U$2601,A9,Cleaned_Data!$K$2:$K$2601) -> 6915595.3 | C9: =COUNTIF(Cleaned_Data!$U$2:$U$2601,A9) -> 119 | I9: Insight Advisory Services | J9: =SUMIF(Cleaned_Data!$D$2:$D$2601,I9,Cleaned_Data!$K$2:$K$2601) -> 20279626 | K9: =J9/$A$4 -> 0.12846258 | L9: =COUNTIFS(Cleaned_Data!$D$2:$D$2601,I9,Cleaned_Data!$Q$2:$Q$2601,"Closed") -> 277 | M9: =COUNTIFS(Cleaned_Data!$D$2:$D$2601,I9,Cleaned_Data!$R$2:$R$2601,"Late") -> 17 | N9: =IF(L9=0,0,(L9-M9)/L9) -> 0.93862816
A10: 2025-03 | B10: =SUMIF(Cleaned_Data!$U$2:$U$2601,A10,Cleaned_Data!$K$2:$K$2601) -> 10956499 | C10: =COUNTIF(Cleaned_Data!$U$2:$U$2601,A10) -> 179 | I10: Prime Workplace India | J10: =SUMIF(Cleaned_Data!$D$2:$D$2601,I10,Cleaned_Data!$K$2:$K$2601) -> 12793887 | K10: =J10/$A$4 -> 0.081043695 | L10: =COUNTIFS(Cleaned_Data!$D$2:$D$2601,I10,Cleaned_Data!$Q$2:$Q$2601,"Closed") -> 280 | M10: =COUNTIFS(Cleaned_Data!$D$2:$D$2601,I10,Cleaned_Data!$R$2:$R$2601,"Late") -> 11 | N10: =IF(L10=0,0,(L10-M10)/L10) -> 0.96071429
A11: 2025-04 | B11: =SUMIF(Cleaned_Data!$U$2:$U$2601,A11,Cleaned_Data!$K$2:$K$2601) -> 7751137.7 | C11: =COUNTIF(Cleaned_Data!$U$2:$U$2601,A11) -> 129 | I11: Nexa Technologies | J11: =SUMIF(Cleaned_Data!$D$2:$D$2601,I11,Cleaned_Data!$K$2:$K$2601) -> 12263850 | K11: =J11/$A$4 -> 0.077686138 | L11: =COUNTIFS(Cleaned_Data!$D$2:$D$2601,I11,Cleaned_Data!$Q$2:$Q$2601,"Closed") -> 123 | M11: =COUNTIFS(Cleaned_Data!$D$2:$D$2601,I11,Cleaned_Data!$R$2:$R$2601,"Late") -> 14 | N11: =IF(L11=0,0,(L11-M11)/L11) -> 0.88617886
A12: 2025-05 | B12: =SUMIF(Cleaned_Data!$U$2:$U$2601,A12,Cleaned_Data!$K$2:$K$2601) -> 9736517 | C12: =COUNTIF(Cleaned_Data!$U$2:$U$2601,A12) -> 144 | I12: Apex Office Solutions | J12: =SUMIF(Cleaned_Data!$D$2:$D$2601,I12,Cleaned_Data!$K$2:$K$2601) -> 12072508 | K12: =J12/$A$4 -> 0.076474074 | L12: =COUNTIFS(Cleaned_Data!$D$2:$D$2601,I12,Cleaned_Data!$Q$2:$Q$2601,"Closed") -> 354 | M12: =COUNTIFS(Cleaned_Data!$D$2:$D$2601,I12,Cleaned_Data!$R$2:$R$2601,"Late") -> 25 | N12: =IF(L12=0,0,(L12-M12)/L12) -> 0.92937853
A13: 2025-06 | B13: =SUMIF(Cleaned_Data!$U$2:$U$2601,A13,Cleaned_Data!$K$2:$K$2601) -> 8315221 | C13: =COUNTIF(Cleaned_Data!$U$2:$U$2601,A13) -> 140 | I13: TalentBridge Consulting | J13: =SUMIF(Cleaned_Data!$D$2:$D$2601,I13,Cleaned_Data!$K$2:$K$2601) -> 11774497 | K13: =J13/$A$4 -> 0.074586299 | L13: =COUNTIFS(Cleaned_Data!$D$2:$D$2601,I13,Cleaned_Data!$Q$2:$Q$2601,"Closed") -> 150 | M13: =COUNTIFS(Cleaned_Data!$D$2:$D$2601,I13,Cleaned_Data!$R$2:$R$2601,"Late") -> 7 | N13: =IF(L13=0,0,(L13-M13)/L13) -> 0.95333333
A14: 2025-07 | B14: =SUMIF(Cleaned_Data!$U$2:$U$2601,A14,Cleaned_Data!$K$2:$K$2601) -> 7115578.2 | C14: =COUNTIF(Cleaned_Data!$U$2:$U$2601,A14) -> 127 | I14: SecureNet Systems | J14: =SUMIF(Cleaned_Data!$D$2:$D$2601,I14,Cleaned_Data!$K$2:$K$2601) -> 11127772 | K14: =J14/$A$4 -> 0.070489579 | L14: =COUNTIFS(Cleaned_Data!$D$2:$D$2601,I14,Cleaned_Data!$Q$2:$Q$2601,"Closed") -> 91 | M14: =COUNTIFS(Cleaned_Data!$D$2:$D$2601,I14,Cleaned_Data!$R$2:$R$2601,"Late") -> 5 | N14: =IF(L14=0,0,(L14-M14)/L14) -> 0.94505495
A15: 2025-08 | B15: =SUMIF(Cleaned_Data!$U$2:$U$2601,A15,Cleaned_Data!$K$2:$K$2601) -> 9123032.4 | C15: =COUNTIF(Cleaned_Data!$U$2:$U$2601,A15) -> 151 | I15: Vertex Digital Systems | J15: =SUMIF(Cleaned_Data!$D$2:$D$2601,I15,Cleaned_Data!$K$2:$K$2601) -> 9926619.4 | K15: =J15/$A$4 -> 0.062880803 | L15: =COUNTIFS(Cleaned_Data!$D$2:$D$2601,I15,Cleaned_Data!$Q$2:$Q$2601,"Closed") -> 85 | M15: =COUNTIFS(Cleaned_Data!$D$2:$D$2601,I15,Cleaned_Data!$R$2:$R$2601,"Late") -> 6 | N15: =IF(L15=0,0,(L15-M15)/L15) -> 0.92941176
A16: 2025-09 | B16: =SUMIF(Cleaned_Data!$U$2:$U$2601,A16,Cleaned_Data!$K$2:$K$2601) -> 8475355 | C16: =COUNTIF(Cleaned_Data!$U$2:$U$2601,A16) -> 152 | I16: StratEdge Partners | J16: =SUMIF(Cleaned_Data!$D$2:$D$2601,I16,Cleaned_Data!$K$2:$K$2601) -> 8985970.7 | K16: =J16/$A$4 -> 0.056922204 | L16: =COUNTIFS(Cleaned_Data!$D$2:$D$2601,I16,Cleaned_Data!$Q$2:$Q$2601,"Closed") -> 130 | M16: =COUNTIFS(Cleaned_Data!$D$2:$D$2601,I16,Cleaned_Data!$R$2:$R$2601,"Late") -> 10 | N16: =IF(L16=0,0,(L16-M16)/L16) -> 0.92307692
A17: 2025-10 | B17: =SUMIF(Cleaned_Data!$U$2:$U$2601,A17,Cleaned_Data!$K$2:$K$2601) -> 9567563.7 | C17: =COUNTIF(Cleaned_Data!$U$2:$U$2601,A17) -> 167 | I17: Urban Maintenance Co. | J17: =SUMIF(Cleaned_Data!$D$2:$D$2601,I17,Cleaned_Data!$K$2:$K$2601) -> 6287986.1 | K17: =J17/$A$4 -> 0.039831649 | L17: =COUNTIFS(Cleaned_Data!$D$2:$D$2601,I17,Cleaned_Data!$Q$2:$Q$2601,"Closed") -> 116 | M17: =COUNTIFS(Cleaned_Data!$D$2:$D$2601,I17,Cleaned_Data!$R$2:$R$2601,"Late") -> 19 | N17: =IF(L17=0,0,(L17-M17)/L17) -> 0.8362069
A18: 2025-11 | B18: =SUMIF(Cleaned_Data!$U$2:$U$2601,A18,Cleaned_Data!$K$2:$K$2601) -> 10569729 | C18: =COUNTIF(Cleaned_Data!$U$2:$U$2601,A18) -> 188 | I18: Metro Business Supplies | J18: =SUMIF(Cleaned_Data!$D$2:$D$2601,I18,Cleaned_Data!$K$2:$K$2601) -> 6022851 | K18: =J18/$A$4 -> 0.038152133 | L18: =COUNTIFS(Cleaned_Data!$D$2:$D$2601,I18,Cleaned_Data!$Q$2:$Q$2601,"Closed") -> 217 | M18: =COUNTIFS(Cleaned_Data!$D$2:$D$2601,I18,Cleaned_Data!$R$2:$R$2601,"Late") -> 48 | N18: =IF(L18=0,0,(L18-M18)/L18) -> 0.77880184
A19: 2025-12 | B19: =SUMIF(Cleaned_Data!$U$2:$U$2601,A19,Cleaned_Data!$K$2:$K$2601) -> 8023721.1 | C19: =COUNTIF(Cleaned_Data!$U$2:$U$2601,A19) -> 123 | I19: FacilityPro Services | J19: =SUMIF(Cleaned_Data!$D$2:$D$2601,I19,Cleaned_Data!$K$2:$K$2601) -> 5551035.8 | K19: =J19/$A$4 -> 0.03516339 | L19: =COUNTIFS(Cleaned_Data!$D$2:$D$2601,I19,Cleaned_Data!$Q$2:$Q$2601,"Closed") -> 106 | M19: =COUNTIFS(Cleaned_Data!$D$2:$D$2601,I19,Cleaned_Data!$R$2:$R$2601,"Late") -> 5 | N19: =IF(L19=0,0,(L19-M19)/L19) -> 0.95283019
... A23: 2026-04 | B23: =SUMIF(Cleaned_Data!$U$2:$U$2601,A23,Cleaned_Data!$K$2:$K$2601) -> 7781307.9 | C23: =COUNTIF(Cleaned_Data!$U$2:$U$2601,A23) -> 130 | I23: BrightReach Media | J23: =SUMIF(Cleaned_Data!$D$2:$D$2601,I23,Cleaned_Data!$K$2:$K$2601) -> 2616316.7 | K23: =J23/$A$4 -> 0.016573225 | L23: =COUNTIFS(Cleaned_Data!$D$2:$D$2601,I23,Cleaned_Data!$Q$2:$Q$2601,"Closed") -> 64 | M23: =COUNTIFS(Cleaned_Data!$D$2:$D$2601,I23,Cleaned_Data!$R$2:$R$2601,"Late") -> 3 | N23: =IF(L23=0,0,(L23-M23)/L23) -> 0.953125
A24: 2026-05 | B24: =SUMIF(Cleaned_Data!$U$2:$U$2601,A24,Cleaned_Data!$K$2:$K$2601) -> 8439161.4 | C24: =COUNTIF(Cleaned_Data!$U$2:$U$2601,A24) -> 134
A25: 2026-06 | B25: =SUMIF(Cleaned_Data!$U$2:$U$2601,A25,Cleaned_Data!$K$2:$K$2601) -> 8750483.3 | C25: =COUNTIF(Cleaned_Data!$U$2:$U$2601,A25) -> 135
I27: Department | J27: Spend_INR | K27: Spend_Share
I28: IT | J28: =SUMIF(Cleaned_Data!$E$2:$E$2601,I28,Cleaned_Data!$K$2:$K$2601) -> 44482040 | K28: =J28/$A$4 -> 0.28177432
A29: Category | B29: Spend_INR | C29: Spend_Share | I29: Operations | J29: =SUMIF(Cleaned_Data!$E$2:$E$2601,I29,Cleaned_Data!$K$2:$K$2601) -> 26975096 | K29: =J29/$A$4 -> 0.17087546
A30: Technology | B30: =SUMIF(Cleaned_Data!$F$2:$F$2601,A30,Cleaned_Data!$K$2:$K$2601) -> 58810102 | C30: =B30/$A$4 -> 0.37253634 | I30: Sales & Marketing | J30: =SUMIF(Cleaned_Data!$E$2:$E$2601,I30,Cleaned_Data!$K$2:$K$2601) -> 25504723 | K30: =J30/$A$4 -> 0.16156129
A31: Professional Services | B31: =SUMIF(Cleaned_Data!$F$2:$F$2601,A31,Cleaned_Data!$K$2:$K$2601) -> 41040093 | C31: =B31/$A$4 -> 0.25997109 | I31: Administration | J31: =SUMIF(Cleaned_Data!$E$2:$E$2601,I31,Cleaned_Data!$K$2:$K$2601) -> 21305236 | K31: =J31/$A$4 -> 0.13495938
A32: Office Supplies | B32: =SUMIF(Cleaned_Data!$F$2:$F$2601,A32,Cleaned_Data!$K$2:$K$2601) -> 24028236 | C32: =B32/$A$4 -> 0.15220839 | I32: Finance | J32: =SUMIF(Cleaned_Data!$E$2:$E$2601,I32,Cleaned_Data!$K$2:$K$2601) -> 21206343 | K32: =J32/$A$4 -> 0.13433293
A33: Facilities | B33: =SUMIF(Cleaned_Data!$F$2:$F$2601,A33,Cleaned_Data!$K$2:$K$2601) -> 18700032 | C33: =B33/$A$4 -> 0.11845655 | I33: Human Resources | J33: =SUMIF(Cleaned_Data!$E$2:$E$2601,I33,Cleaned_Data!$K$2:$K$2601) -> 18390631 | K33: =J33/$A$4 -> 0.11649662
A34: Safety | B34: =SUMIF(Cleaned_Data!$F$2:$F$2601,A34,Cleaned_Data!$K$2:$K$2601) -> 9877382.2 | C34: =B34/$A$4 -> 0.062568907
A35: Marketing | B35: =SUMIF(Cleaned_Data!$F$2:$F$2601,A35,Cleaned_Data!$K$2:$K$2601) -> 5408222.2 | C35: =B35/$A$4 -> 0.034258728
A39: Item_ID | B39: Item_Description | C39: Lowest_Price_Vendor | D39: Avg_Low_Price | E39: Highest_Price_Vendor | F39: Avg_High_Price | G39: Price_Gap_%
A40: ITM008 | B40: Network Switch - 24 Port | C40: CoreTech Solutions | D40: 15401.436 | E40: Vertex Digital Systems | F40: 18474.241 | G40: 0.19951421
A41: ITM007 | B41: USB-C Docking Station | C41: CoreTech Solutions | D41: 8141.0154 | E41: Vertex Digital Systems | F41: 9727.9928 | G41: 0.19493604
A42: ITM006 | B42: Business Laptop - Standard | C42: CoreTech Solutions | D42: 53554.882 | E42: Vertex Digital Systems | F42: 63476.974 | G42: 0.18526962
A43: ITM009 | B43: Annual Software License | C43: CoreTech Solutions | D43: 20691.944 | E43: Vertex Digital Systems | F43: 24464.364 | G43: 0.18231351
A44: ITM004 | B44: Wireless Keyboard & Mouse | C44: CoreTech Solutions | D44: 1696.7586 | E44: Vertex Digital Systems | F44: 1993.3271 | G44: 0.17478532
A45: ITM005 | B45: 24-inch Business Monitor | C45: CoreTech Solutions | D45: 10235.147 | E45: Vertex Digital Systems | F45: 12018.929 | G45: 0.17428012
A46: ITM001 | B46: A4 Copier Paper - 500 Sheets | C46: Metro Business Supplies | D46: 230.2027 | E46: Prime Workplace India | F46: 267.39769 | G46: 0.16157495
A47: ITM002 | B47: Black Toner Cartridge | C47: Metro Business Supplies | D47: 2979.9648 | E47: Prime Workplace India | F47: 3445.6963 | G47: 0.1562876
A48: ITM003 | B48: Ergonomic Office Chair | C48: Metro Business Supplies | D48: 7369.4118 | E48: Prime Workplace India | F48: 8482.2012 | G48: 0.15100111
A49: ITM012 | B49: LED Panel Light | C49: Urban Maintenance Co. | D49: 1587.913 | E49: Prime Workplace India | F49: 1780.162 | G49: 0.1210702

Sheet Dashboard
A1: Vendor Spend & Procurement Analytics | N1: Vendor | O1: On_Time_Pct
N2: CoreTech Solutions | O2: 77.6
N3: Insight Advisory Services | O3: 93.9
A4: Total Spend | D4: Total POs | G4: On-Time Delivery | J4: Top 3 Vendor Share | N4: Prime Workplace India | O4: 96.1
A5: ="₹"&TEXT(Excel_Analysis!A4,"#,##0") -> ₹157,864,068 | D5: =TEXT(Excel_Analysis!B4,"#,##0") -> 2,600 | G5: =TEXT(Excel_Analysis!D4,"0.0%") -> 90.2% | J5: =TEXT(Excel_Analysis!F4,"0.0%") -> 37.1% | N5: Nexa Technologies | O5: 88.6
N6: Apex Office Solutions | O6: 92.9
N7: TalentBridge Consulting | O7: 95.3
N8: SecureNet Systems | O8: 94.5
N9: Vertex Digital Systems | O9: 92.9
A41: Validated Findings & Recommendations
A42: 1. Technology is the largest spend category at ₹58,810,102, representing 37.3% of total procurement spend.
A43: 2. CoreTech Solutions is the largest vendor at ₹25,491,861 (16.1% of spend), but its on-time delivery rate is only 77.6%.
A44: 3. The top three vendors account for 37.1% of total spend, showing a meaningful but not extreme concentration risk.
A45: 4. The largest same-item price gap is for Network Switch - 24 Port: average prices differ by 20.0% between CoreTech Solutions and Vertex Digital Systems.
A46: 5. Metro Business Supplies offers relatively lower office-supply pricing but has an on-time rate of 77.9%; vendor selection should balance cost and delivery reliability.
A47: 6. Vertex Digital Systems has an on-time rate of 92.9%, materially stronger than CoreTech, but generally at higher technology-item prices.
A50: Recommendation: use item-level price benchmarks during vendor negotiations, review high-spend vendors with weaker delivery performance, and consider split-award sourcing where lower price and higher reliability come from different vendors.

Sheet Project_Guide
A1: VENDOR SPEND & PROCUREMENT ANALYTICS
A2: Business Scenario | B2: A multi-location company wants to understand procurement spend, vendor concentration, price inconsistencies, and delivery performance to identify cost-saving and vendor-management opportunities.
A3: Target Role | B3: Entry-level Business Analyst / Data Analyst
A4: Tools Used | B4: Excel, SQL, Power BI
A5: Data Period | B5: January 2025 to June 2026
A6: Dataset Size | B6: 2,600 purchase-order line records
A7: Currency | B7: Indian Rupees (INR)
A9: Workflow | B9: Raw data → Data cleaning → Excel analysis → SQL analysis → Power BI-ready model → Business insights
A11: Business Questions
A12: 1 | B12: How much is the company spending, and how is spend changing over time?
A13: 2 | B13: Which vendors, categories, departments, and regions account for the most spend?
A14: 3 | B14: Is procurement overly dependent on a small number of vendors?
A15: 4 | B15: Are different vendors charging materially different prices for the same items?
A16: 5 | B16: Which vendors provide the best balance of cost and delivery reliability?
A17: 6 | B17: Where are late deliveries concentrated?
A18: 7 | B18: What practical actions could management take based on the findings?
A20: Cleaning Performed | B20: Trimmed vendor names; standardized category capitalization; standardized payment terms; standardized buyer names; retained legitimate blank actual-delivery dates for open POs.
A22: Portfolio Note | B22: This is a synthetic portfolio dataset created to demonstrate a realistic procurement analytics workflow. Findings shown in the workbook are calculated from the generated data.

Sheet Data_Dictionary
A1: Field | B1: Description
A2: PO_Number | B2: Unique purchase-order line identifier in this project.
A3: PO_Date | B3: Date the purchase order was created.
A4: Vendor_ID | B4: Unique vendor identifier.
A5: Vendor_Name | B5: Vendor supplying the product or service.
A6: Department | B6: Internal department responsible for the purchase.
A7: Category | B7: High-level procurement category.
A8: Item_ID | B8: Unique item/service identifier.
A9: Item_Description | B9: Description of the purchased item or service.
A10: Quantity | B10: Number of units purchased.
A11: Unit_Price_INR | B11: Price paid per unit in INR.
A12: PO_Amount_INR | B12: Quantity multiplied by unit price.
... A24: On_Time_Flag | B24: 1 for on-time closed PO, 0 for late closed PO, blank for open PO.
